<mujoco model="Rack_Single_Server">
    <compiler angle="degree" coordinate="local" autolimits="true"/>
    <option gravity="0 0 -9.81" timestep="0.0004" integrator="implicitfast" iterations="150" tolerance="1e-8" ls_iterations="20"/>

    <asset>
        <texture type="skybox" builtin="gradient" rgb1="0.3 0.5 0.7" rgb2="0 0 0" width="512" height="512"/>
        <material name="rack_metal" rgba="0.1 0.1 0.1 1" reflectance="0.2"/>
        <material name="glass_door" rgba="0.1 0.5 0.8 0.2" reflectance="0.5"/>
        <material name="cable_yellow" rgba="1 0.9 0 1"/>
        <material name="switch_face" rgba="0.8 0.8 0.8 1"/>
        <material name="led_green" rgba="0.15 1.0 0.25 1" reflectance="0.35" specular="0.45" shininess="0.35"/>
        <material name="led_red" rgba="0.95 0.12 0.12 1" reflectance="0.35" specular="0.45" shininess="0.35"/>
        <texture name="device_barcode_tex" type="2d" file="device_barcode.png"/>
        <material name="device_barcode" texture="device_barcode_tex" texuniform="false" texrepeat="1 1" reflectance="0.25"/>
        <mesh name="device_barcode_mesh" file="device_barcode.obj"/>
    </asset>

    <worldbody>
        <body name="scene" pos="0 0 0" euler="0 0 270">
        <light pos="1 1 3" dir="-0.3 -0.3 -1" directional="true"/>
        <geom name="floor" type="plane" size="4 4 0.1" pos="0 0 0" rgba="0.9 0.9 0.9 1"/>

        <body name="cabinet" pos="0 0 0">
            <geom name="left_wall" type="box" size="0.4 0.02 0.9" pos="0 0.3 0.9" material="rack_metal"/>
            <geom name="right_wall" type="box" size="0.4 0.02 0.9" pos="0 -0.3 0.9" material="rack_metal"/>
            <geom name="top_cap" type="box" size="0.4 0.3 0.02" pos="0 0 1.8" material="rack_metal"/>

            <body name="glass_door" pos="0.4 0.3 0.9">
                <joint name="door_hinge" type="hinge" axis="0 0 1" range="0 150" damping="2.0"/>
                <geom name="door_visual" type="box" size="0.01 0.3 0.9" pos="0 -0.3 0" material="glass_door"/>
                <geom name="handle" type="capsule" size="0.02 0.1" pos="0.03 -0.55 0" rgba="0.7 0.7 0.7 1"/>
            </body>

            <!-- 하부 빈 슬롯 empty_00~20 (피치 0.05m) -->
            <body name="empty_00" pos="0.1 0 0.125">
                <joint name="empty_00_slide" type="slide" axis="1 0 0" range="0 0.32" damping="8" frictionloss="1"/>
                <geom name="empty_00_tray" type="box" size="0.25 0.24 0.004" pos="0 0 -0.022" material="rack_metal" friction="1 0.005 0.0001"/>
            </body>
            <body name="empty_01" pos="0.1 0 0.175">
                <joint name="empty_01_slide" type="slide" axis="1 0 0" range="0 0.32" damping="8" frictionloss="1"/>
                <geom name="empty_01_tray" type="box" size="0.25 0.24 0.004" pos="0 0 -0.022" material="rack_metal" friction="1 0.005 0.0001"/>
            </body>
            <body name="empty_02" pos="0.1 0 0.225">
                <joint name="empty_02_slide" type="slide" axis="1 0 0" range="0 0.32" damping="8" frictionloss="1"/>
                <geom name="empty_02_tray" type="box" size="0.25 0.24 0.004" pos="0 0 -0.022" material="rack_metal" friction="1 0.005 0.0001"/>
            </body>
            <body name="empty_03" pos="0.1 0 0.275">
                <joint name="empty_03_slide" type="slide" axis="1 0 0" range="0 0.32" damping="8" frictionloss="1"/>
                <geom name="empty_03_tray" type="box" size="0.25 0.24 0.004" pos="0 0 -0.022" material="rack_metal" friction="1 0.005 0.0001"/>
            </body>
            <body name="empty_04" pos="0.1 0 0.325">
                <joint name="empty_04_slide" type="slide" axis="1 0 0" range="0 0.32" damping="8" frictionloss="1"/>
                <geom name="empty_04_tray" type="box" size="0.25 0.24 0.004" pos="0 0 -0.022" material="rack_metal" friction="1 0.005 0.0001"/>
            </body>
            <body name="empty_05" pos="0.1 0 0.375">
                <joint name="empty_05_slide" type="slide" axis="1 0 0" range="0 0.32" damping="8" frictionloss="1"/>
                <geom name="empty_05_tray" type="box" size="0.25 0.24 0.004" pos="0 0 -0.022" material="rack_metal" friction="1 0.005 0.0001"/>
            </body>
            <body name="empty_06" pos="0.1 0 0.425">
                <joint name="empty_06_slide" type="slide" axis="1 0 0" range="0 0.32" damping="8" frictionloss="1"/>
                <geom name="empty_06_tray" type="box" size="0.25 0.24 0.004" pos="0 0 -0.022" material="rack_metal" friction="1 0.005 0.0001"/>
            </body>
            <body name="empty_07" pos="0.1 0 0.475">
                <joint name="empty_07_slide" type="slide" axis="1 0 0" range="0 0.32" damping="8" frictionloss="1"/>
                <geom name="empty_07_tray" type="box" size="0.25 0.24 0.004" pos="0 0 -0.022" material="rack_metal" friction="1 0.005 0.0001"/>
            </body>
            <body name="empty_08" pos="0.1 0 0.525">
                <joint name="empty_08_slide" type="slide" axis="1 0 0" range="0 0.32" damping="8" frictionloss="1"/>
                <geom name="empty_08_tray" type="box" size="0.25 0.24 0.004" pos="0 0 -0.022" material="rack_metal" friction="1 0.005 0.0001"/>
            </body>
            <body name="empty_09" pos="0.1 0 0.575">
                <joint name="empty_09_slide" type="slide" axis="1 0 0" range="0 0.32" damping="8" frictionloss="1"/>
                <geom name="empty_09_tray" type="box" size="0.25 0.24 0.004" pos="0 0 -0.022" material="rack_metal" friction="1 0.005 0.0001"/>
            </body>
            <body name="empty_10" pos="0.1 0 0.625">
                <joint name="empty_10_slide" type="slide" axis="1 0 0" range="0 0.32" damping="8" frictionloss="1"/>
                <geom name="empty_10_tray" type="box" size="0.25 0.24 0.004" pos="0 0 -0.022" material="rack_metal" friction="1 0.005 0.0001"/>
            </body>
            <body name="empty_11" pos="0.1 0 0.675">
                <joint name="empty_11_slide" type="slide" axis="1 0 0" range="0 0.32" damping="8" frictionloss="1"/>
                <geom name="empty_11_tray" type="box" size="0.25 0.24 0.004" pos="0 0 -0.022" material="rack_metal" friction="1 0.005 0.0001"/>
            </body>
            <body name="empty_12" pos="0.1 0 0.725">
                <joint name="empty_12_slide" type="slide" axis="1 0 0" range="0 0.32" damping="8" frictionloss="1"/>
                <geom name="empty_12_tray" type="box" size="0.25 0.24 0.004" pos="0 0 -0.022" material="rack_metal" friction="1 0.005 0.0001"/>
            </body>
            <body name="empty_13" pos="0.1 0 0.775">
                <joint name="empty_13_slide" type="slide" axis="1 0 0" range="0 0.32" damping="8" frictionloss="1"/>
                <geom name="empty_13_tray" type="box" size="0.25 0.24 0.004" pos="0 0 -0.022" material="rack_metal" friction="1 0.005 0.0001"/>
            </body>
            <body name="empty_14" pos="0.1 0 0.825">
                <joint name="empty_14_slide" type="slide" axis="1 0 0" range="0 0.32" damping="8" frictionloss="1"/>
                <geom name="empty_14_tray" type="box" size="0.25 0.24 0.004" pos="0 0 -0.022" material="rack_metal" friction="1 0.005 0.0001"/>
            </body>
            <body name="empty_15" pos="0.1 0 0.875">
                <joint name="empty_15_slide" type="slide" axis="1 0 0" range="0 0.32" damping="8" frictionloss="1"/>
                <geom name="empty_15_tray" type="box" size="0.25 0.24 0.004" pos="0 0 -0.022" material="rack_metal" friction="1 0.005 0.0001"/>
            </body>
            <body name="empty_16" pos="0.1 0 0.925">
                <joint name="empty_16_slide" type="slide" axis="1 0 0" range="0 0.32" damping="8" frictionloss="1"/>
                <geom name="empty_16_tray" type="box" size="0.25 0.24 0.004" pos="0 0 -0.022" material="rack_metal" friction="1 0.005 0.0001"/>
            </body>
            <body name="empty_17" pos="0.1 0 0.975">
                <joint name="empty_17_slide" type="slide" axis="1 0 0" range="0 0.32" damping="8" frictionloss="1"/>
                <geom name="empty_17_tray" type="box" size="0.25 0.24 0.004" pos="0 0 -0.022" material="rack_metal" friction="1 0.005 0.0001"/>
            </body>
            <body name="empty_18" pos="0.1 0 1.025">
                <joint name="empty_18_slide" type="slide" axis="1 0 0" range="0 0.32" damping="8" frictionloss="1"/>
                <geom name="empty_18_tray" type="box" size="0.25 0.24 0.004" pos="0 0 -0.022" material="rack_metal" friction="1 0.005 0.0001"/>
            </body>
            <body name="empty_19" pos="0.1 0 1.075">
                <joint name="empty_19_slide" type="slide" axis="1 0 0" range="0 0.32" damping="8" frictionloss="1"/>
                <geom name="empty_19_tray" type="box" size="0.25 0.24 0.004" pos="0 0 -0.022" material="rack_metal" friction="1 0.005 0.0001"/>
            </body>
            <body name="empty_20" pos="0.1 0 1.125">
                <joint name="empty_20_slide" type="slide" axis="1 0 0" range="0 0.32" damping="8" frictionloss="1"/>
                <geom name="empty_20_tray" type="box" size="0.25 0.24 0.004" pos="0 0 -0.022" material="rack_metal" friction="1 0.005 0.0001"/>
            </body>

            <!-- 유일한 서버: 최하단(z=1.175). 랜 포트·케이블 텐던·빨간 LED 1개 -->
            <body name="srv_00" pos="0.1 0 1.175">
                <joint name="srv_00_shelf_slide" type="slide" axis="1 0 0" range="0 0.32" damping="8" frictionloss="1"/>
                <geom name="srv_00_geom" type="box" size="0.25 0.24 0.02" material="switch_face"/>
                <geom name="srv_00_barcode" type="mesh" mesh="device_barcode_mesh" pos="0.252 -0.18 0" euler="0 180 0" material="device_barcode" contype="0" conaffinity="0"/>
                <site name="srv_00_lan_0" pos="-0.25 -0.18 -0.007" size="0.0035" rgba="0.12 0.32 0.55 1"/>
                <site name="srv_00_lan_1" pos="-0.25 -0.135 -0.007" size="0.0035" rgba="0.12 0.32 0.55 1"/>
                <site name="srv_00_lan_2" pos="-0.25 -0.09 -0.007" size="0.0035" rgba="0.12 0.32 0.55 1"/>
                <site name="srv_00_lan_3" pos="-0.25 -0.045 -0.007" size="0.0035" rgba="0.12 0.32 0.55 1"/>
                <site name="srv_00_lan_4" pos="-0.25 0.00 -0.007" size="0.0035" rgba="0.12 0.32 0.55 1"/>
                <site name="srv_00_lan_5" pos="-0.25 0.045 -0.007" size="0.0035" rgba="0.12 0.32 0.55 1"/>
                <site name="srv_00_lan_6" pos="-0.25 0.09 -0.007" size="0.0035" rgba="0.12 0.32 0.55 1"/>
                <site name="srv_00_lan_7" pos="-0.25 0.135 -0.007" size="0.0035" rgba="0.12 0.32 0.55 1"/>
                <site name="srv_00_lan_8" pos="-0.25 0.18 -0.007" size="0.0035" rgba="0.12 0.32 0.55 1"/>
                <site name="srv_00_lan_9" pos="-0.25 -0.18 0.007" size="0.0035" rgba="0.12 0.32 0.55 1"/>
                <site name="srv_00_lan_10" pos="-0.25 -0.135 0.007" size="0.0035" rgba="0.12 0.32 0.55 1"/>
                <site name="srv_00_lan_11" pos="-0.25 -0.09 0.007" size="0.0035" rgba="0.12 0.32 0.55 1"/>
                <site name="srv_00_lan_12" pos="-0.25 -0.045 0.007" size="0.0035" rgba="0.12 0.32 0.55 1"/>
                <site name="srv_00_lan_13" pos="-0.25 0.00 0.007" size="0.0035" rgba="0.12 0.32 0.55 1"/>
                <site name="srv_00_lan_14" pos="-0.25 0.045 0.007" size="0.0035" rgba="0.12 0.32 0.55 1"/>
                <site name="srv_00_lan_15" pos="-0.25 0.09 0.007" size="0.0035" rgba="0.12 0.32 0.55 1"/>
                <site name="srv_00_lan_16" pos="-0.25 0.135 0.007" size="0.0035" rgba="0.12 0.32 0.55 1"/>
                <site name="srv_00_lan_17" pos="-0.25 0.18 0.007" size="0.0035" rgba="0.12 0.32 0.55 1"/>
                <geom name="srv_00_led_0" type="sphere" size="0.002" pos="-0.257 -0.18 -0.015" material="led_green" contype="0" conaffinity="0"/>
                <geom name="srv_00_led_1" type="sphere" size="0.002" pos="-0.257 -0.135 -0.015" material="led_green" contype="0" conaffinity="0"/>
                <geom name="srv_00_led_2" type="sphere" size="0.002" pos="-0.257 -0.09 -0.015" material="led_green" contype="0" conaffinity="0"/>
                <geom name="srv_00_led_3" type="sphere" size="0.002" pos="-0.257 -0.045 -0.015" material="led_green" contype="0" conaffinity="0"/>
                <geom name="srv_00_led_4" type="sphere" size="0.002" pos="-0.257 0.00 -0.015" material="led_green" contype="0" conaffinity="0"/>
                <geom name="srv_00_led_5" type="sphere" size="0.002" pos="-0.257 0.045 -0.015" material="led_green" contype="0" conaffinity="0"/>
                <geom name="srv_00_led_6" type="sphere" size="0.002" pos="-0.257 0.09 -0.015" material="led_green" contype="0" conaffinity="0"/>
                <geom name="srv_00_led_7" type="sphere" size="0.002" pos="-0.257 0.135 -0.015" material="led_green" contype="0" conaffinity="0"/>
                <geom name="srv_00_led_8" type="sphere" size="0.002" pos="-0.257 0.18 -0.015" material="led_green" contype="0" conaffinity="0"/>
                <geom name="srv_00_led_9" type="sphere" size="0.002" pos="-0.257 -0.18 0.015" material="led_red" contype="0" conaffinity="0"/>
                <geom name="srv_00_led_10" type="sphere" size="0.002" pos="-0.257 -0.135 0.015" material="led_green" contype="0" conaffinity="0"/>
                <geom name="srv_00_led_11" type="sphere" size="0.002" pos="-0.257 -0.09 0.015" material="led_green" contype="0" conaffinity="0"/>
                <geom name="srv_00_led_12" type="sphere" size="0.002" pos="-0.257 -0.045 0.015" material="led_green" contype="0" conaffinity="0"/>
                <geom name="srv_00_led_13" type="sphere" size="0.002" pos="-0.257 0.00 0.015" material="led_green" contype="0" conaffinity="0"/>
                <geom name="srv_00_led_14" type="sphere" size="0.002" pos="-0.257 0.045 0.015" material="led_green" contype="0" conaffinity="0"/>
                <geom name="srv_00_led_15" type="sphere" size="0.002" pos="-0.257 0.09 0.015" material="led_green" contype="0" conaffinity="0"/>
                <geom name="srv_00_led_16" type="sphere" size="0.002" pos="-0.257 0.135 0.015" material="led_green" contype="0" conaffinity="0"/>
                <geom name="srv_00_led_17" type="sphere" size="0.002" pos="-0.257 0.18 0.015" material="led_green" contype="0" conaffinity="0"/>
                <geom name="srv_00_shelf_geom" type="box" size="0.25 0.24 0.004" pos="0 0 -0.022" material="rack_metal" friction="1 0.005 0.0001"/>
            </body>

            <!-- 기존 다중 서버 자리: 빈 슬라이드만 (피치 0.08m) -->
            <body name="slide_u01" pos="0.1 0 1.255">
                <joint name="slide_u01_joint" type="slide" axis="1 0 0" range="0 0.32" damping="8" frictionloss="1"/>
                <geom name="slide_u01_tray" type="box" size="0.25 0.24 0.004" pos="0 0 -0.022" material="rack_metal" friction="1 0.005 0.0001"/>
            </body>
            <body name="slide_u02" pos="0.1 0 1.335">
                <joint name="slide_u02_joint" type="slide" axis="1 0 0" range="0 0.32" damping="8" frictionloss="1"/>
                <geom name="slide_u02_tray" type="box" size="0.25 0.24 0.004" pos="0 0 -0.022" material="rack_metal" friction="1 0.005 0.0001"/>
            </body>
            <body name="slide_u03" pos="0.1 0 1.415">
                <joint name="slide_u03_joint" type="slide" axis="1 0 0" range="0 0.32" damping="8" frictionloss="1"/>
                <geom name="slide_u03_tray" type="box" size="0.25 0.24 0.004" pos="0 0 -0.022" material="rack_metal" friction="1 0.005 0.0001"/>
            </body>
            <body name="slide_u04" pos="0.1 0 1.495">
                <joint name="slide_u04_joint" type="slide" axis="1 0 0" range="0 0.32" damping="8" frictionloss="1"/>
                <geom name="slide_u04_tray" type="box" size="0.25 0.24 0.004" pos="0 0 -0.022" material="rack_metal" friction="1 0.005 0.0001"/>
            </body>
            <body name="slide_u05" pos="0.1 0 1.575">
                <joint name="slide_u05_joint" type="slide" axis="1 0 0" range="0 0.32" damping="8" frictionloss="1"/>
                <geom name="slide_u05_tray" type="box" size="0.25 0.24 0.004" pos="0 0 -0.022" material="rack_metal" friction="1 0.005 0.0001"/>
            </body>
            <body name="slide_u06" pos="0.1 0 1.655">
                <joint name="slide_u06_joint" type="slide" axis="1 0 0" range="0 0.32" damping="8" frictionloss="1"/>
                <geom name="slide_u06_tray" type="box" size="0.25 0.24 0.004" pos="0 0 -0.022" material="rack_metal" friction="1 0.005 0.0001"/>
            </body>
            <body name="slide_u07" pos="0.1 0 1.735">
                <joint name="slide_u07_joint" type="slide" axis="1 0 0" range="0 0.32" damping="8" frictionloss="1"/>
                <geom name="slide_u07_tray" type="box" size="0.25 0.24 0.004" pos="0 0 -0.022" material="rack_metal" friction="1 0.005 0.0001"/>
            </body>
        </body>

        <site name="lan_rt1_a" pos="-0.42 -0.20 1.163" size="0.002" rgba="0 0 0 0"/>
        <site name="lan_rt1_b" pos="-0.42 -0.20 0.03" size="0.002" rgba="0 0 0 0"/>
        <site name="lan_rt1_c" pos="-0.42 0.22 0.03" size="0.002" rgba="0 0 0 0"/>
        <site name="lan_rt1_d" pos="-0.48 0.28 0.03" size="0.002" rgba="0 0 0 0"/>
        <site name="floor_target_1" pos="-0.55 0.20 0" size="0.02" rgba="0 0 0 0"/>

        </body>
        <camera name="rack_front" pos="0 2.5 1.0" xyaxes="-1 0 0 0 0 1"/>
    </worldbody>

    <tendon>
        <spatial name="cable_tendon_1" width="0.005" material="cable_yellow">
            <site site="srv_00_lan_0"/>
            <site site="lan_rt1_a"/>
            <site site="lan_rt1_b"/>
            <site site="lan_rt1_c"/>
            <site site="lan_rt1_d"/>
            <site site="floor_target_1"/>
        </spatial>
    </tendon>
</mujoco>
